Workbook

Sheet PowerBI_Simulation
A1: Bug Tracking & Quality Assurance Dashboard
A2: Data last updated on 12/25/2025
A4: Start date | C4: End date | E4: Project | G4: Team | I4: Sprint | K4: Severity
A5: 1/1/2023 | C5: 12/30/2023 | E5: All | G5: All | I5: Sprint 4 | K5: All
A7: Open Bugs (count) | C7: New Bugs (count) | E7: Active Bugs (count) | G7: Resolved Bugs (count) | I7: Verified Bugs (count) | K7: Closed Bugs (count) | M7: Reopened Bugs (count)
A8: 8.4K | C8: 2.1K | E8: 3.5K | G8: 4.8K | I8: 4.2K | K8: 3.9K | M8: 0.6K
A9: vs prev: 7.2K | B9: +16.67% | C9: vs prev: 2.8K | D9: -25% | E9: vs prev: 3.2K | F9: +9.37% | G9: vs prev: 3.9K | H9: +23% | I9: vs prev: 3.5K | J9: +20% | K9: vs prev: 3.1K | L9: +26% | M9: vs prev: 0.8K | N9: -25%
A11: Multi-Reopened Bugs (count) | C11: Escaped Bugs (count) | E11: Regression Bugs (count) | G11: Critical Bugs (count) | I11: High Severity Bugs (count) | K11: Medium Severity Bugs (count) | M11: Low Severity Bugs (count)
A12: 0.2K | C12: 0.4K | E12: 0.3K | G12: 0.8K | I12: 1.9K | K12: 3.2K | M12: 2.5K
A13: vs prev: 0.3K | B13: -33% | C13: vs prev: 0.6K | D13: -33% | E13: vs prev: 0.4K | F13: -25% | G13: vs prev: 1.1K | H13: -27% | I13: vs prev: 1.6K | J13: +19% | K13: vs prev: 2.8K | L13: +14% | M13: vs prev: 1.7K | N13: +47%
A15: P0 Bugs (count) | C15: P1 Bugs (count) | E15: P2 Bugs (count) | G15: Blocking Bugs (count) | I15: Customer Reported Bugs (count) | K15: Security Bugs (count) | M15: Performance Bugs (count)
A16: 0.5K | C16: 1.3K | E16: 2.8K | G16: 0.7K | I16: 1.1K | K16: 0.3K | M16: 0.5K
A17: vs prev: 0.7K | B17: -29% | C17: vs prev: 1.1K | D17: +18% | E17: vs prev: 2.4K | F17: +17% | G17: vs prev: 0.9K | H17: -22% | I17: vs prev: 1.4K | J17: -21% | K17: vs prev: 0.2K | L17: +50% | M17: vs prev: 0.4K | N17: +25%
A19: User Interface Bugs (count) | C19: Data Integrity Bugs (count)
A20: 1.8K | C20: 0.4K
A21: vs prev: 1.5K | B21: +20% | C21: vs prev: 0.3K | D21: +33%
A27: Status | B27: Count | E27: Severity | F27: Count | I27: Week | J27: Metric 1 | K27: Metric 2
A28: Verified | B28: 980 | E28: Medium | F28: 3200 | I28: W1 | J28: 100 | K28: 95
A29: Closed | B29: 650 | E29: Critical | F29: 800 | I29: W2 | J29: 110 | K29: 102
A30: In Progress | B30: 360 | E30: High | F30: 1900 | I30: W3 | J30: 105 | K30: 98
A31: Resolved | B31: 180 | I31: W4 | J31: 120 | K31: 110

Sheet KPIs_Detail
A1: Code | B1: Metric Name | C1: Value | D1: Formula (as Text) | E1: Description
A2: B03 | B2: B03_Revenue_at_Risk | C2: 0 | D2: =SUM('Bugs'[BusinessImpact]) | E2: Auto-generated from MD: Revenue at Risk
A3: B04 | B3: B04_Avg_Revenue_Impact_per_Bug | C3: 0 | D3: =AVERAGE('Bugs'[BusinessImpact]) | E3: Auto-generated from MD: Avg Revenue Impact per Bug
A4: B05 | B4: B05_High_Impact_Bugs | C4: 0 | D4: =CALCULATE(COUNTA(raw_data!A:A)-1, 'Bugs'[BusinessImpact] > 10000) | E4: Auto-generated from MD: High Impact Bugs
A5: B09 | B5: B09_Security_Risk_Level | C5: 0 | D5: =SWITCH(TRUE(), [V23_Security_Bugs] > 10, "High", [V23_Security_Bugs] > 5, "Medium", "Low" ) | E5: Auto-generated from MD: Security Risk Level
A6: B10 | B6: B10_Compliance_Risk_Bugs | C6: 0 | D6: =CALCULATE(COUNTA(raw_data!A:A)-1, 'Bugs'[Category] = "Compliance") | E6: Auto-generated from MD: Compliance Risk Bugs
A7: B11 | B7: B11_Data_Loss_Risk_Bugs | C7: 0 | D7: =CALCULATE(COUNTA(raw_data!A:A)-1, 'Bugs'[Category] = "Data Loss") | E7: Auto-generated from MD: Data Loss Risk Bugs
A8: B12 | B8: B12_Critical_Business_Impact_Bugs | C8: 0 | D8: =CALCULATE( COUNTA(raw_data!A:A)-1, raw_data!D:D = "Critical", 'Bugs'[BusinessImpact] > 0 ) | E8: Auto-generated from MD: Critical Business Impact Bugs
A9: B13 | B9: B13_Cost_of_Poor_Quality | C9: 0 | D9: =[J18_Project_Cost_of_Quality] | E9: Auto-generated from MD: Cost of Poor Quality
A10: B14 | B10: B14_Avg_Impact_by_Severity | C10: 0 | D10: =AVERAGEX( VALUES(raw_data!D:D), CALCULATE(AVERAGE('Bugs'[BusinessImpact])) ) | E10: Auto-generated from MD: Avg Impact by Severity
A11: B15 | B11: B15_Total_Business_Impact | C11: 0 | D11: =SUM('Bugs'[BusinessImpact]) | E11: Auto-generated from MD: Total Business Impact
A12: B16 | B12: B16_Impact_per_Module | C12: 0 | D12: =AVERAGEX( VALUES('Bugs'[ModuleName]), CALCULATE(SUM('Bugs'[BusinessImpact])) ) | E12: Auto-generated from MD: Impact per Module
A13: B17 | B13: B17_High_Severity_Impact | C13: 0 | D13: =CALCULATE( SUM('Bugs'[BusinessImpact]), raw_data!D:D IN {"Critical", "High"} ) | E13: Auto-generated from MD: High Severity Impact
A14: B18 | B14: B18_Production_Bug_Impact | C14: 0 | D14: =CALCULATE( SUM('Bugs'[BusinessImpact]), 'Bugs'[Tags] CONTAINS "Production" ) | E14: Auto-generated from MD: Production Bug Impact
A15: B19 | B15: B19_Escaped_Bug_Impact | C15: 0 | D15: =CALCULATE( SUM('Bugs'[BusinessImpact]), raw_data!I:I = TRUE ) | E15: Auto-generated from MD: Escaped Bug Impact
A16: B20 | B16: B20_Impact_Risk_Score | C16: 0 | D16: =([B15_Total_Business_Impact] * 0.4) + ([B19_Escaped_Bug_Impact] * 0.35) + ([B17_High_Severity_Impact] * 0.25) | E16: Auto-generated from MD: Impact Risk Score
A17: B21 | B17: B21_Avg_Resolution_Cost | C17: 0 | D17: =AVERAGE('Bugs'[TotalEffortHrs]) * 100 | E17: Auto-generated from MD: Avg Resolution Cost
A18: B22 | B18: B22_Security_Bug_Impact | C18: 0 | D18: =CALCULATE( SUM('Bugs'[BusinessImpact]), 'Bugs'[Category] = "Security" ) | E18: Auto-generated from MD: Security Bug Impact
A19: B23 | B19: B23_Performance_Bug_Impact | C19: 0 | D19: =CALCULATE( SUM('Bugs'[BusinessImpact]), 'Bugs'[Category] = "Performance" ) | E19: Auto-generated from MD: Performance Bug Impact
A20: B24 | B20: B24_Compliance_Cost | C20: 0 | D20: =CALCULATE( SUM('Bugs'[TotalEffortHrs]), 'Bugs'[Category] = "Compliance" ) * 100 | E20: Auto-generated from MD: Compliance Cost
A21: B25 | B21: B25_Revenue_Impact_by_Priority | C21: 0 | D21: =CALCULATE( SUM('Bugs'[BusinessImpact]), ALLEXCEPT('Bugs', raw_data!E:E) ) | E21: Auto-generated from MD: Revenue Impact by Priority
A22: C01 | B22: C01_Customer_Reported_Bugs | C22: 0 | D22: =[V22_Customer_Reported_Bugs] | E22: Auto-generated from MD: Customer Reported Bugs
A23: C02 | B23: C02_Customer_Bug_Rate | C23: 0 | D23: =DIVIDE([C01_Customer_Reported_Bugs], [V01_Total_Bugs], 0) | E23: Auto-generated from MD: Customer Bug Rate
A24: C03 | B24: C03_Avg_Customer_Response_Time | C24: 0 | D24: =AVERAGEX( FILTER('Bugs', raw_data!I:I = TRUE), 'Bugs'[ResponseTimeHrs] ) | E24: Auto-generated from MD: Avg Customer Response Time
A25: C04 | B25: C04_Avg_Customer_Resolution_Time | C25: 0 | D25: =AVERAGEX( FILTER('Bugs', raw_data!I:I = TRUE), 'Bugs'[LeadTimeHrs] ) | E25: Auto-generated from MD: Avg Customer Resolution Time
A26: C05 | B26: C05_Customer_Critical_Bugs | C26: 0 | D26: =CALCULATE( COUNTA(raw_data!A:A)-1, raw_data!I:I = TRUE, raw_data!D:D = "Critical" ) | E26: Auto-generated from MD: Customer Critical Bugs
A27: C06 | B27: C06_Customer_High_Bugs | C27: 0 | D27: =CALCULATE( COUNTA(raw_data!A:A)-1, raw_data!I:I = TRUE, raw_data!D:D = "High" ) | E27: Auto-generated from MD: Customer High Bugs
A28: C07 | B28: C07_Customer_Satisfaction_Index | C28: 0 | D28: =1 - ([C02_Customer_Bug_Rate] * 0.4 + [Q01_Escape_Rate] * 0.6) | E28: Auto-generated from MD: Customer Satisfaction Index
A29: C08 | B29: C08_Customer_Impact_Score | C29: 0 | D29: =([C05_Customer_Critical_Bugs] * 10) + ([C06_Customer_High_Bugs] * 5) + ([C01_Customer_Reported_Bugs] * 1) | E29: Auto-generated from MD: Customer Impact Score
A30: C09 | B30: C09_SLA_Compliance_Rate | C30: 0 | D30: =Complex formula (see DAX reference) | E30: Auto-generated from MD: SLA Compliance Rate
A31: C10 | B31: C10_Customer_Reopen_Rate | C31: 0 | D31: =DIVIDE( CALCULATE(COUNTA(raw_data!A:A)-1, raw_data!AM:AM > 0, raw_data!I:I = TRUE), [C01_Customer_Reported_Bugs], 0 ) | E31: Auto-generated from MD: Customer Reopen Rate
A32: C11 | B32: C11_Avg_Customer_Effort | C32: 0 | D32: =AVERAGEX( FILTER('Bugs', raw_data!I:I = TRUE), 'Bugs'[TotalEffortHrs] ) | E32: Auto-generated from MD: Avg Customer Effort
A33: C12 | B33: C12_Customer_Escalation_Rate | C33: 0 | D33: =DIVIDE( CALCULATE(COUNTA(raw_data!A:A)-1, raw_data!E:E = "P0", raw_data!I:I = TRUE), [C01_Customer_Reported_Bugs], 0 ) | E33: Auto-generated from MD: Customer Escalation Rate
A34: C14 | B34: C14_Customer_Experience_Score | C34: 0 | D34: =([C07_Customer_Satisfaction_Index] * 0.4) + ((1 - [C10_Customer_Reopen_Rate]) * 0.3) + ([C09_SLA_Compliance_Rate] * 0.3) | E34: Auto-generated from MD: Customer Experience Score
A35: C16 | B35: C16_Escaped_Bug_Fix_Rate | C35: 0 | D35: =DIVIDE( CALCULATE(COUNTA(raw_data!A:A)-1, raw_data!F:F IN {"Resolved", "Done", "Closed"}, raw_data!I:I = TRUE), [C01_Customer_Reported_Bugs], 0 ) | E35: Auto-generated from MD: Escaped Bug Fix Rate
A36: C17 | B36: C17_Customer_Waiting_Bugs | C36: 0 | D36: =CALCULATE( COUNTA(raw_data!A:A)-1, raw_data!F:F NOT IN {"Resolved", "Done", "Closed"}, raw_data!I:I = TRUE ) | E36: Auto-generated from MD: Customer Waiting Bugs
A37: C18 | B37: C18_Avg_Customer_Wait_Time | C37: 0 | D37: =AVERAGEX( FILTER('Bugs', raw_data!I:I = TRUE), 'Bugs'[WaitTimeHrs] ) | E37: Auto-generated from MD: Avg Customer Wait Time
A38: C19 | B38: C19_Customer_Bug_Trend | C38: 0 | D38: =Complex formula (see DAX reference) | E38: Auto-generated from MD: Customer Bug Trend
A39: C20 | B39: C20_Customer_Priority_Response | C39: 0 | D39: =AVERAGEX( FILTER('Bugs', raw_data!I:I = TRUE && raw_data!E:E = "P0"), 'Bugs'[ResponseTimeHrs] ) | E39: Auto-generated from MD: Customer Priority Response
A40: CR01 | B40: CR01_By_Design_Count | C40: 1 | D40: =COUNTIF(raw_data!BR:BR,"By Design") | E40: Bugs closed as By Design
...

Sheet raw_data
A1: BugID | B1: Title | C1: Description | D1: Severity | E1: Priority | F1: State | G1: Category | H1: IsRegression | I1: is_escaped | J1: ProjectID | K1: ProjectName | L1: TeamName | M1: TeamID | N1: ModuleID | O1: ModuleName | P1: SprintName | Q1: SprintID | R1: Tags | S1: ExternalTicketID | T1: Comments | U1: ReporterName | V1: ReporterID | W1: AssigneeName | X1: AssigneeID | Y1: VerifierName | Z1: VerifierID | AA1: ResolverName | AB1: ResolverID | AC1: CreatedDate | AD1: TriageDate | AE1: AssignedDate | AF1: StartedDate | AG1: InProgressDate | AH1: ReadyForRetestDate | AI1: ResolvedDate | AJ1: VerifiedDate | AK1: DoneDate | AL1: ClosedDate | AM1: LastModifiedDate | AN1: DueDate | AO1: ReopenCount | AP1: FirstReopenDate | AQ1: LastReopenDate | AR1: PreviousState | AS1: StateTransitionCount | AT1: TriageDurationHrs | AU1: ActiveDurationHrs | AV1: InProgressDurationHrs | AW1: ReadyForRetestDurationHrs | AX1: StateHistory | AY1: AssigneeChangeCount | AZ1: StateChangeCount | BA1: FixAttempts | BB1: AnalysisEffortHrs | BC1: DevEffortHrs | BD1: FixEffortHrs | BE1: TestEffortHrs | BF1: ReopenEffortHrs | BG1: TotalEffortHrs | BH1: EstimatedEffortHrs | BI1: LeadTimeHrs | BJ1: CycleTimeHrs | BK1: ResponseTimeHrs | BL1: WaitTimeHrs | BM1: ActiveWorkTimeHrs | BN1: AgeDays | BO1: RootCause | BP1: Resolution | BQ1: CloseReason | BR1: TestCaseID | BS1: IsDuplicate | BT1: DuplicateOfBugID | BU1: RetestPassCount | BV1: RetestFailCount
A2: 194977 | B2: چک شوددر کجا nameAndnationalcode در جدول entitytableکجا ست میشود؟ | C2: تکمیل توضیحات: چک شوددر کجا nameAndnationalcode در جدول entitytab... | D2: Medium | E2: P0 | F2: Done | G2: Data | H2: FALSE | I2: FALSE | J2: PRJ-001 | K2: Dem System | L2: Team Gamma | M2: T03 | N2: M09 | O2: Dem\DemBiz\SP_88 | P2: Sprint 23 | Q2: S23 | R2: Data;Medium | T2: کامنت 0 مورد | U2: Mohammad Safari | V2: U093 | W2: Fateme Akbari | X2: U511 | Y2: Zahra Ebrahimi | Z2: U002 | AA2: Mohammad Safari | AB2: U093 | AC2: 2024-06-12 | AD2: 2024-06-12 08:00:00 | AE2: 2024-06-12 09:00:00 | AF2: 2024-06-13 22:00:00 | AG2: 2024-06-13 22:00:00 | AH2: 2024-06-15 13:00:00 | AI2: 2024-06-16 07:00:00 | AJ2: 2024-06-16 13:00:00 | AK2: 2024-06-16 13:00:00 | AM2: 2024-06-16 13:00:00 | AN2: 2024-08-05 | AO2: 0 | AR2: Resolved | AS2: 8 | AT2: 1 | AU2: 37 | AV2: 39 | AW2: 18 | AX2: [{"state": "Open", "timestamp": "2024-06-12T00:00:00"}, {"state": "Triage", "timestamp": "2024-06-12T08:00:00"}] | AY2: 3 | AZ2: 10 | BA2: 1 | BB2: 5.0717325 | BC2: 17.699182 | BD2: 12.884326 | BE2: 15.790016 | BF2: 0 | BG2: 51.445256 | BH2: 54.334189 | BK2: 9 | BL2: 56 | BM2: 39 | BN2: 561.77079 | BO2: Coding | BP2: Fixed | BS2: FALSE | BU2: 3 | BV2: 2
A3: 183712 | B3: گزارش کارتابل یوزر ها در 1382 | C3: تکمیل توضیحات: گزارش کارتابل یوزر ها در 1382... | D3: Low | E3: P2 | F3: Triage | G3: Security | H3: TRUE | I3: FALSE | J3: PRJ-001 | K3: Dem System | L3: Team Beta | M3: T02 | N3: M09 | O3: Dem\DemBiz\SP_88 | P3: Sprint 23 | Q3: S23 | R3: Security;Low | S3: EXT-183712 | T3: کامنت 5 مورد | U3: Sara Ahmadi | V3: U091 | W3: Mina Hosseini | X3: U860 | AC3: 2024-01-27 | AD3: 2024-01-28 20:00:00 | AM3: 2024-01-28 20:00:00 | AN3: 2024-03-21 | AO3: 0 | AR3: Open | AS3: 4 | AX3: [{"state": "Open", "timestamp": "2024-01-27T00:00:00"}, {"state": "Triage", "timestamp": "2024-01-28T20:00:00"}] | AY3: 4 | AZ3: 4 | BA3: 1 | BB3: 4.2700927 | BC3: 38.699538 | BD3: 1.3834282 | BE3: 12.300673 | BF3: 0 | BG3: 56.653732 | BH3: 62.74182 | BL3: 0 | BM3: 0 | BN3: 698.77079 | BR3: TC-5506 | BS3: FALSE | BU3: 0 | BV3: 0
A4: 186097 | B4: گزارش های کارتابل رییس واحد باگ دارد | C4: تکمیل توضیحات: گزارش های کارتابل رییس واحد باگ دارد... | D4: Medium | E4: P2 | F4: Active | G4: Integration | H4: TRUE | I4: TRUE | J4: PRJ-001 | K4: Dem System | L4: Team Delta | M4: T04 | N4: M09 | O4: Dem\DemBiz\SP_88 | P4: Sprint 25 | Q4: S25 | R4: Integration;Medium | S4: EXT-186097 | T4: کامنت 5 مورد | U4: Mina Hosseini | V4: U860 | W4: Mohammad Safari | X4: U093 | AC4: 2024-05-19 | AD4: 2024-05-19 06:00:00 | AE4: 2024-05-20 01:00:00 | AM4: 2024-05-20 01:00:00 | AN4: 2024-06-22 | AO4: 0 | AR4: Triage | AS4: 2 | AT4: 19 | AX4: [{"state": "Open", "timestamp": "2024-05-19T00:00:00"}, {"state": "Triage", "timestamp": "2024-05-19T06:00:00"}] | AY4: 2 | AZ4: 3 | BA4: 1 | BB4: 0.88609063 | BC4: 38.581179 | BD4: 7.804946 | BE4: 6.6438938 | BF4: 0 | BG4: 53.91611 | BH4: 63.270702 | BK4: 25 | BL4: 19 | BM4: 0 | BN4: 585.77079 | BR4: TC-3286 | BS4: FALSE | BU4: 0 | BV4: 0
A5: 186218 | B5: گزارش کارتابل یوزر های اداره کل وصول مطالبات باگ دارد | C5: تکمیل توضیحات: گزارش کارتابل یوزر های اداره کل وصول مطالبات باگ د... | D5: Medium | E5: P2 | F5: Closed | G5: Performance | H5: TRUE | I5: FALSE | J5: PRJ-001 | K5: Dem System | L5: Team Alpha | M5: T01 | N5: M09 | O5: Dem\DemBiz\SP_88 | P5: Sprint 27 | Q5: S27 | R5: Performance;Medium | S5: EXT-186218 | T5: کامنت 0 مورد | U5: Sara Ahmadi | V5: U091 | W5: Mohammad Safari | X5: U093 | Y5: Reza Mohammadi | Z5: U493 | AA5: Mina Hosseini | AB5: U860 | AC5: 2024-01-09 | AD5: 2024-01-09 02:00:00 | AE5: 2024-01-09 05:00:00 | AF5: 2024-01-10 10:00:00 | AG5: 2024-01-10 10:00:00 | AH5: 2024-01-11 23:00:00 | AI5: 2024-01-13 11:00:00 | AJ5: 2024-01-14 08:00:00 | AK5: 2024-01-14 09:00:00 | AL5: 2024-01-15 21:00:00 | AM5: 2024-01-15 21:00:00 | AN5: 2024-01-28 | AO5: 3 | AP5: 2024-01-19 21:00:00 | AQ5: 2024-01-22 21:00:00 | AR5: Done | AS5: 9 | AT5: 3 | AU5: 29 | AV5: 37 | AW5: 36 | AX5: [{"state": "Open", "timestamp": "2024-01-09T00:00:00"}, {"state": "Triage", "timestamp": "2024-01-09T02:00:00"}] | AY5: 4 | AZ5: 9 | BA5: 4 | BB5: 2.5898485 | BC5: 34.267369 | BD5: 12.704268 | BE5: 2.2525108 | BF5: 23.169552 | BG5: 74.983548 | BH5: 74.913462 | BI5: 165 | BJ5: 131 | BK5: 5 | BL5: 68 | BM5: 37 | BN5: 716.77079 | BO5: Integration | BP5: Fixed | BQ5: Duplicate | BS5: TRUE | BT5: 191994 | BU5: 2 | BV5: 0
A6: 187649 | B6: تعداد سند های ، کارتابل یوزر جوان خیلی زیاد است | C6: تکمیل توضیحات: تعداد سند های ، کارتابل یوزر جوان خیلی زیاد است... | D6: High | E6: P3 | F6: Done | G6: Security | H6: TRUE | I6: TRUE | J6: PRJ-001 | K6: Dem System | L6: Team Beta | M6: T02 | N6: M09 | O6: Dem\DemBiz\SP_88 | P6: Sprint 26 | Q6: S26 | R6: Security;High | T6: کامنت 5 مورد | U6: Hassan Karimi | V6: U829 | W6: Hassan Karimi | X6: U829 | Y6: Hassan Karimi | Z6: U829 | AA6: Zahra Ebrahimi | AB6: U002 | AC6: 2024-05-30 | AD6: 2024-05-30 18:00:00 | AE6: 2024-05-30 19:00:00 | AF6: 2024-05-31 17:00:00 | AG6: 2024-05-31 17:00:00 | AH6: 2024-06-04 18:00:00 | AI6: 2024-06-06 01:00:00 | AJ6: 2024-06-06 13:00:00 | AK6: 2024-06-06 13:00:00 | AM6: 2024-06-06 13:00:00 | AN6: 2024-06-23 | AO6: 0 | AR6: Resolved | AS6: 8 | AT6: 1 | AU6: 22 | AV6: 97 | AW6: 31 | AX6: [{"state": "Open", "timestamp": "2024-05-30T00:00:00"}, {"state": "Triage", "timestamp": "2024-05-30T18:00:00"}] | AY6: 4 | AZ6: 10 | BA6: 1 | BB6: 7.3119941 | BC6: 12.483507 | BD6: 10.311157 | BE6: 12.657204 | BF6: 0 | BG6: 42.763862 | BH6: 32.164932 | BK6: 19 | BL6: 54 | BM6: 97 | BN6: 574.77079 | BO6: Testing | BP6: Fixed | BS6: FALSE | BU6: 1 | BV6: 0
A7: 188959 | B7: کمبو محل مصرف ،در فرم ثبت درخواست ، ایران وسط شهر ها هست | C7: تکمیل توضیحات: کمبو محل مصرف ،در فرم ثبت درخواست ، ایران وسط شهر ... | D7: High | E7: P1 | F7: Open | G7: Data | H7: FALSE | I7: FALSE | J7: PRJ-001 | K7: Dem System | L7: Team Alpha | M7: T01 | N7: M09 | O7: Dem\DemBiz\SP_88 | P7: Sprint 24 | Q7: S24 | R7: Data;High | T7: کامنت 4 مورد | U7: Fateme Akbari | V7: U511 | W7: Ali Rezaei | X7: U374 | AC7: 2024-02-09 | AM7: 2024-02-09 00:00:00 | AN7: 2024-02-29 | AO7: 0 | AS7: 3 | AX7: [{"state": "Open", "timestamp": "2024-02-09T00:00:00"}, {"state": "Triage", "timestamp": ""}] | AY7: 1 | AZ7: 5 | BA7: 1 | BB7: 2.2967142 | BC7: 16.018811 | BD7: 17.201552 | BE7: 9.3760637 | BF7: 0 | BG7: 44.893141 | BH7: 45.892639 | BL7: 0 | BM7: 0 | BN7: 685.77079 | BS7: FALSE | BU7: 0 | BV7: 0
A8: 189035 | B8: دکمه ذخیره ویرایش عقد | C8: تکمیل توضیحات: دکمه ذخیره ویرایش عقد... | D8: Critical | E8: P2 | F8: Triage | G8: Backend | H8: TRUE | I8: FALSE | J8: PRJ-001 | K8: Dem System | L8: Team Delta | M8: T04 | N8: M09 | O8: Dem\DemBiz\SP_88 | P8: Sprint 26 | Q8: S26 | R8: Backend;Critical | T8: کامنت 2 مورد | U8: Sara Ahmadi | V8: U091 | W8: Mina Hosseini | X8: U860 | AC8: 2024-03-27 | AD8: 2024-03-27 07:00:00 | AM8: 2024-03-27 07:00:00 | AN8: 2024-04-08 | AO8: 0 | AR8: Open | AS8: 1 | AX8: [{"state": "Open", "timestamp": "2024-03-27T00:00:00"}, {"state": "Triage", "timestamp": "2024-03-27T07:00:00"}] | AY8: 2 | AZ8: 2 | BA8: 1 | BB8: 1.5867115 | BC8: 34.19433 | BD8: 13.344526 | BE8: 7.3633301 | BF8: 0 | BG8: 56.488898 | BH8: 59.432233 | BL8: 0 | BM8: 0 | BN8: 638.77079 | BR8: TC-7912 | BS8: FALSE | BU8: 0 | BV8: 0
A9: 189703 | B9: باگ کاربرگ بررسی | C9: تکمیل توضیحات: باگ کاربرگ بررسی... | D9: Low | E9: P3 | F9: Done | G9: Security | H9: FALSE | I9: FALSE | J9: PRJ-001 | K9: Dem System | L9: Team Gamma | M9: T03 | N9: M09 | O9: Dem\DemBiz\SP_88 | P9: Sprint 24 | Q9: S24 | R9: Security;Low | S9: EXT-189703 | T9: کامنت 5 مورد | U9: Mina Hosseini | V9: U860 | W9: Zahra Ebrahimi | X9: U002 | Y9: Zahra Ebrahimi | Z9: U002 | AA9: Hassan Karimi | AB9: U829 | AC9: 2024-04-07 | AD9: 2024-04-07 07:00:00 | AE9: 2024-04-07 19:00:00 | AF9: 2024-04-09 17:00:00 | AG9: 2024-04-09 17:00:00 | AH9: 2024-04-13 06:00:00 | AI9: 2024-04-14 02:00:00 | AJ9: 2024-04-14 05:00:00 | AK9: 2024-04-14 05:00:00 | AM9: 2024-04-14 05:00:00 | AN9: 2024-05-30 | AO9: 0 | AR9: Resolved | AS9: 6 | AT9: 12 | AU9: 46 | AV9: 85 | AW9: 20 | AX9: [{"state": "Open", "timestamp": "2024-04-07T00:00:00"}, {"state": "Triage", "timestamp": "2024-04-07T07:00:00"}] | AY9: 2 | AZ9: 6 | BA9: 1 | BB9: 4.1708957 | BC9: 13.359958 | BD9: 3.6772213 | BE9: 14.595316 | BF9: 0 | BG9: 35.803391 | BH9: 41.07593 | BK9: 19 | BL9: 78 | BM9: 85 | BN9: 627.77079 | BO9: Config | BP9: Fixed | BR9: TC-2535 | BS9: FALSE | BU9: 1 | BV9: 1
A10: 189796 | B10: کمبو نام مشتری در گزارش نسبت های مالی ، رکورد نال نمایش می هد/گزارش | C10: تکمیل توضیحات: کمبو نام مشتری در گزارش نسبت های مالی ، رکورد نال ... | D10: Medium | E10: P1 | F10: Open | G10: Backend | H10: FALSE | I10: TRUE | J10: PRJ-001 | K10: Dem System | L10: Team Delta | M10: T04 | N10: M09 | O10: Dem\DemBiz\SP_88 | P10: Sprint 27 | Q10: S27 | R10: Backend;Medium | T10: کامنت 2 مورد | U10: Ali Rezaei | V10: U374 | W10: Mohammad Safari | X10: U093 | AC10: 2024-04-27 | AM10: 2024-04-27 00:00:00 | AN10: 2024-06-07 | AO10: 0 | AS10: 2 | AX10: [{"state": "Open", "timestamp": "2024-04-27T00:00:00"}, {"state": "Triage", "timestamp": ""}] | AY10: 2 | AZ10: 4 | BA10: 1 | BB10: 7.8923784 | BC10: 7.6102171 | BD10: 1.8760906 | BE10: 2.6679622 | BF10: 0 | BG10: 20.046648 | BH10: 19.22465 | BL10: 0 | BM10: 0 | BN10: 607.77079 | BR10: TC-9279 | BS10: FALSE | BU10: 0 | BV10: 0
A11: 189801 | B11: کمبو نام شخص در گزارش مدیران و سهامداران/شرکا، کورد نال نمایش می دهد/ گزارش | C11: تکمیل توضیحات: کمبو نام شخص در گزارش مدیران و سهامداران/شرکا، کور... | D11: Medium | E11: P1 | F11: Active | G11: Integration | H11: TRUE | I11: FALSE | J11: PRJ-001 | K11: Dem System | L11: Team Beta | M11: T02 | N11: M09 | O11: Dem\DemBiz\SP_88 | P11: Sprint 24 | Q11: S24 | R11: Integration;Medium | S11: EXT-189801 | T11: کامنت 0 مورد | U11: Mohammad Safari | V11: U093 | W11: Reza Mohammadi | X11: U493 | AC11: 2024-02-01 | AD11: 2024-02-02 01:00:00 | AE11: 2024-02-02 04:00:00 | AM11: 2024-02-02 04:00:00 | AN11: 2024-03-14 | AO11: 0 | AR11: Triage | AS11: 3 | AT11: 3 | AX11: [{"state": "Open", "timestamp": "2024-02-01T00:00:00"}, {"state": "Triage", "timestamp": "2024-02-02T01:00:00"}] | AY11: 4 | AZ11: 4 | BA11: 1 | BB11: 2.3154145 | BC11: 22.715249 | BD11: 13.027176 | BE11: 8.3893766 | BF11: 0 | BG11: 46.447216 | BH11: 36.068501 | BK11: 28 | BL11: 3 | BM11: 0 | BN11: 693.77079 | BS11: FALSE | BU11: 0 | BV11: 0
A12: 189803 | B12: نامرتب بودن ، کمبو واحد کارشناسی / گزارش | C12: تکمیل توضیحات: نامرتب بودن ، کمبو واحد کارشناسی / گزارش... | D12: Critical | E12: P2 | F12: Resolved | G12: Performance | H12: FALSE | I12: FALSE | J12: PRJ-001 | K12: Dem System | L12: Team Gamma | M12: T03 | N12: M09 | O12: Dem\DemBiz\SP_88 | P12: Sprint 25 | Q12: S25 | R12: Performance;Critical | S12: EXT-189803 | T12: کامنت 2 مورد | U12: Hassan Karimi | V12: U829 | W12: Mina Hosseini | X12: U860 | Y12: Fateme Akbari | Z12: U511 | AA12: Fateme Akbari | AB12: U511 | AC12: 2024-03-16 | AD12: 2024-03-17 17:00:00 | AE12: 2024-03-18 13:00:00 | AF12: 2024-03-20 13:00:00 | AG12: 2024-03-20 13:00:00 | AH12: 2024-03-23 22:00:00 | AI12: 2024-03-24 14:00:00 | AM12: 2024-03-24 14:00:00 | AN12: 2024-05-07 | AO12: 0 | AR12: Ready for Retest | AS12: 7 | AT12: 20 | AU12: 48 | AV12: 81 | AW12: 16 | AX12: [{"state": "Open", "timestamp": "2024-03-16T00:00:00"}, {"state": "Triage", "timestamp": "2024-03-17T17:00:00"}] | AY12: 3 | AZ12: 9 | BA12: 1 | BB12: 5.5410166 | BC12: 37.510036 | BD12: 1.0169706 | BE12: 1.1703047 | BF12: 0 | BG12: 45.238328 | BH12: 39.369358 | BK12: 61 | BL12: 84 | BM12: 81 | BN12: 649.77079 | BO12: Config | BP12: Fixed | BR12: TC-9928 | BS12: FALSE | BU12: 0 | BV12: 2
A13: 189805 | B13: عدم نمایش عقد تقسیط - تقسیط ضمانت نامه ، در کمبو نوع عقود/گزارش | C13: تکمیل توضیحات: عدم نمایش عقد تقسیط - تقسیط ضمانت نامه ، در کمبو ن... | D13: Low | E13: P1 | F13: Done | G13: UI | H13: FALSE | I13: FALSE | J13: PRJ-001 | K13: Dem System | L13: Team Beta | M13: T02 | N13: M09 | O13: Dem\DemBiz\SP_88 | P13: Sprint 25 | Q13: S25 | R13: UI;Low | T13: کامنت 3 مورد | U13: Ali Rezaei | V13: U374 | W13: Hassan Karimi | X13: U829 | Y13: Ali Rezaei | Z13: U374 | AA13: Ali Rezaei | AB13: U374 | AC13: 2024-01-18 | AD13: 2024-01-18 03:00:00 | AE13: 2024-01-19 01:00:00 | AF13: 2024-01-20 08:00:00 | AG13: 2024-01-20 08:00:00 | AH13: 2024-01-24 18:00:00 | AI13: 2024-01-25 16:00:00 | AJ13: 2024-01-25 20:00:00 | AK13: 2024-01-25 20:00:00 | AM13: 2024-01-25 20:00:00 | AN13: 2024-02-08 | AO13: 0 | AR13: Resolved | AS13: 8 | AT13: 22 | AU13: 31 | AV13: 106 | AW13: 22 | AX13: [{"state": "Open", "timestamp": "2024-01-18T00:00:00"}, {"state": "Triage", "timestamp": "2024-01-18T03:00:00"}] | AY13: 2 | AZ13: 10 | BA13: 1 | BB13: 6.2121471 | BC13: 28.145162 | BD13: 11.922624 | BE13: 8.0299096 | BF13: 0 | BG13: 54.309843 | BH13: 49.848255 | BK13: 25 | BL13: 75 | BM13: 106 | BN13: 707.77079 | BO13: Integration | BP13: By Design | BR13: TC-8359 | BS13: FALSE | BU13: 1 | BV13: 1
A14: 189808 | B14: کمبو شماره مشتری در گزارش نظارتی ، رکورد نال نمایش می دهد/گزارش | C14: تکمیل توضیحات: کمبو شماره مشتری در گزارش نظارتی ، رکورد نال نمایش... | D14: Low | E14: P3 | F14: Done | G14: Performance | H14: TRUE | I14: FALSE | J14: PRJ-001 | K14: Dem System | L14: Team Gamma | M14: T03 | N14: M09 | O14: Dem\DemBiz\SP_88 | P14: Sprint 25 | Q14: S25 | R14: Performance;Low | S14: EXT-189808 | T14: کامنت 1 مورد | U14: Ali Rezaei | V14: U374 | W14: Zahra Ebrahimi | X14: U002 | Y14: Zahra Ebrahimi | Z14: U002 | AA14: Ali Rezaei | AB14: U374 | AC14: 2024-01-26 | AD14: 2024-01-27 01:00:00 | AE14: 2024-01-27 10:00:00 | AF14: 2024-01-29 22:00:00 | AG14: 2024-01-29 22:00:00 | AH14: 2024-02-02 15:00:00 | AI14: 2024-02-03 18:00:00 | AJ14: 2024-02-04 01:00:00 | AK14: 2024-02-04 01:00:00 | AM14: 2024-02-04 01:00:00 | AN14: 2024-02-25 | AO14: 0 | AR14: Resolved | AS14: 8 | AT14: 9 | AU14: 60 | AV14: 89 | AW14: 27 | AX14: [{"state": "Open", "timestamp": "2024-01-26T00:00:00"}, {"state": "Triage", "timestamp": "2024-01-27T01:00:00"}] | AY14: 4 | AZ14: 8 | BA14: 1 | BB14: 2.2822816 | BC14: 23.232386 | BD14: 18.83449 | BE14: 1.8445491 | BF14: 0 | BG14: 46.193706 | BH14: 50.237981 | BK14: 34 | BL14: 96 | BM14: 89 | BN14: 699.77079 | BO14: Integration | BP14: Fixed | BR14: TC-1106 | BS14: FALSE | BU14: 1 | BV14: 0
A15: 190117 | B15: کمبو مدیریت شعب در گزارشات ، منو سامانه باگ دارد | C15: تکمیل توضیحات: کمبو مدیریت شعب در گزارشات ، منو سامانه باگ دارد... | D15: High | E15: P3 | F15: Active | G15: Security | H15: FALSE | I15: FALSE | J15: PRJ-001 | K15: Dem System | L15: Team Alpha | M15: T01 | N15: M09 | O15: Dem\DemBiz\SP_88 | P15: Sprint 25 | Q15: S25 | R15: Security;High | S15: EXT-190117 | T15: کامنت 3 مورد | U15: Ali Rezaei | V15: U374 | W15: Ali Rezaei | X15: U374 | AC15: 2024-03-31 | AD15: 2024-03-31 14:00:00 | AE15: 2024-04-01 12:00:00 | AM15: 2024-04-01 12:00:00 | AN15: 2024-04-24 | AO15: 0 | AR15: Triage | AS15: 4 | AT15: 22 | AX15: [{"state": "Open", "timestamp": "2024-03-31T00:00:00"}, {"state": "Triage", "timestamp": "2024-03-31T14:00:00"}] | AY15: 1 | AZ15: 6 | BA15: 1 | BB15: 5.9616226 | BC15: 4.7898833 | BD15: 11.721746 | BE15: 2.7822687 | BF15: 0 | BG15: 25.255521 | BH15: 26.328047 | BK15: 36 | BL15: 22 | BM15: 0 | BN15: 634.77079 | BS15: FALSE | BU15: 0 | BV15: 0
A16: 190121 | B16: اصلاح تایتل گزارش درخواست های وارده به اداره کل اعتبارات | C16: تکمیل توضیحات: اصلاح تایتل گزارش درخواست های وارده به اداره کل اع... | D16: High | E16: P2 | F16: Closed | G16: Backend | H16: FALSE | I16: FALSE | J16: PRJ-001 | K16: Dem System | L16: Team Alpha | M16: T01 | N16: M09 | O16: Dem\DemBiz\SP_88 | P16: Sprint 26 | Q16: S26 | R16: Backend;High | T16: کامنت 0 مورد | U16: Reza Mohammadi | V16: U493 | W16: Ali Rezaei | X16: U374 | Y16: Reza Mohammadi | Z16: U493 | AA16: Hassan Karimi | AB16: U829 | AC16: 2024-06-28 | AD16: 2024-06-29 20:00:00 | AE16: 2024-06-30 17:00:00 | AF16: 2024-07-01 04:00:00 | AG16: 2024-07-01 04:00:00 | AH16: 2024-07-04 17:00:00 | AI16: 2024-07-06 13:00:00 | AJ16: 2024-07-06 20:00:00 | AK16: 2024-07-07 00:00:00 | AL16: 2024-07-07 11:00:00 | AM16: 2024-07-07 11:00:00 | AN16: 2024-08-03 | AO16: 3 | AP16: 2024-07-12 11:00:00 | AQ16: 2024-07-17 11:00:00 | AR16: Done | AS16: 10 | AT16: 21 | AU16: 11 | AV16: 85 | AW16: 44 | AX16: [{"state": "Open", "timestamp": "2024-06-28T00:00:00"}, {"state": "Triage", "timestamp": "2024-06-29T20:00:00"}] | AY16: 3 | AZ16: 10 | BA16: 4 | BB16: 3.2583735 | BC16: 24.985282 | BD16: 8.0693136 | BE16: 2.7628937 | BF16: 21.122393 | BG16: 60.198256 | BH16: 55.00062 | BI16: 227 | BJ16: 151 | BK16: 65 | BL16: 76 | BM16: 85 | BN16: 545.77079 | BO16: Config | BP16: Fixed | BQ16: Completed | BR16: TC-7924 | BS16: FALSE | BU16: 2 | BV16: 0
A17: 190125 | B17: کمبو معرف در گزارش تسهیلات متفرقه ، رکورد نال نمایش می دهد | C17: تکمیل توضیحات: کمبو معرف در گزارش تسهیلات متفرقه ، رکورد نال نمای... | D17: High | E17: P3 | F17: In Progress | G17: Backend | H17: FALSE | I17: FALSE | J17: PRJ-001 | K17: Dem System | L17: Team Alpha | M17: T01 | N17: M09 | O17: Dem\DemBiz\SP_88 | P17: Sprint 27 | Q17: S27 | R17: Backend;High | T17: کامنت 5 مورد | U17: Mohammad Safari | V17: U093 | W17: Hassan Karimi | X17: U829 | AC17: 2024-06-25 | AD17: 2024-06-26 12:00:00 | AE17: 2024-06-26 20:00:00 | AF17: 2024-06-28 15:00:00 | AG17: 2024-06-28 15:00:00 | AM17: 2024-06-28 15:00:00 | AN17: 2024-08-24 | AO17: 0 | AR17: Active | AS17: 3 | AT17: 8 | AU17: 43 | AX17: [{"state": "Open", "timestamp": "2024-06-25T00:00:00"}, {"state": "Triage", "timestamp": "2024-06-26T12:00:00"}] | AY17: 1 | AZ17: 5 | BA17: 1 | BB17: 5.2422937 | BC17: 39.6121 | BD17: 13.04412 | BE17: 10.738155 | BF17: 0 | BG17: 68.636669 | BH17: 88.67234 | BK17: 44 | BL17: 51 | BM17: 0 | BN17: 548.77079 | BR17: TC-3547 | BS17: FALSE | BU17: 0 | BV17: 0
A18: 190142 | B18: عدم دریافت گزارش مدت زمان توقف کارپرونده وارده به اداره کل اعتبارات | C18: تکمیل توضیحات: عدم دریافت گزارش مدت زمان توقف کارپرونده وارده به ... | D18: High | E18: P3 | F18: In Progress | G18: Data | H18: FALSE | I18: FALSE | J18: PRJ-001 | K18: Dem System | L18: Team Delta | M18: T04 | N18: M09 | O18: Dem\DemBiz\SP_88 | P18: Sprint 24 | Q18: S24 | R18: Data;High | S18: EXT-190142 | T18: کامنت 5 مورد | U18: Fateme Akbari | V18: U511 | W18: Hassan Karimi | X18: U829 | AC18: 2024-01-15 | AD18: 2024-01-15 15:00:00 | AE18: 2024-01-15 17:00:00 | AF18: 2024-01-17 11:00:00 | AG18: 2024-01-17 11:00:00 | AM18: 2024-01-17 11:00:00 | AN18: 2024-02-16 | AO18: 0 | AR18: Active | AS18: 6 | AT18: 2 | AU18: 42 | AX18: [{"state": "Open", "timestamp": "2024-01-15T00:00:00"}, {"state": "Triage", "timestamp": "2024-01-15T15:00:00"}] | AY18: 3 | AZ18: 7 | BA18: 1 | BB18: 5.2514728 | BC18: 6.4632766 | BD18: 9.4359314 | BE18: 12.190673 | BF18: 0 | BG18: 33.341354 | BH18: 35.457359 | BK18: 17 | BL18: 44 | BM18: 0 | BN18: 710.77079 | BR18: TC-6514 | BS18: FALSE | BU18: 0 | BV18: 0
A19: 190225 | B19: خالی بودن کمبو واحد کارشناسی در گزارش آمار تجمیعی واحد ها | C19: تکمیل توضیحات: خالی بودن کمبو واحد کارشناسی در گزارش آمار تجمیعی ... | D19: Medium | E19: P1 | F19: Closed | G19: Backend | H19: FALSE | I19: FALSE | J19: PRJ-001 | K19: Dem System | L19: Team Beta | M19: T02 | N19: M09 | O19: Dem\DemBiz\SP_88 | P19: Sprint 24 | Q19: S24 | R19: Backend;Medium | T19: کامنت 2 مورد | U19: Zahra Ebrahimi | V19: U002 | W19: Reza Mohammadi | X19: U493 | Y19: Mohammad Safari | Z19: U093 | AA19: Mohammad Safari | AB19: U093 | AC19: 2024-03-09 | AD19: 2024-03-09 05:00:00 | AE19: 2024-03-09 12:00:00 | AF19: 2024-03-11 06:00:00 | AG19: 2024-03-11 06:00:00 | AH19: 2024-03-12 17:00:00 | AI19: 2024-03-14 14:00:00 | AJ19: 2024-03-15 07:00:00 | AK19: 2024-03-15 14:00:00 | AL19: 2024-03-17 08:00:00 | AM19: 2024-03-17 08:00:00 | AN19: 2024-04-14 | AO19: 1 | AP19: 2024-03-22 08:00:00 | AQ19: 2024-03-22 08:00:00 | AR19: Done | AS19: 10 | AT19: 7 | AU19: 42 | AV19: 35 | AW19: 45 | AX19: [{"state": "Open", "timestamp": "2024-03-09T00:00:00"}, {"state": "Triage", "timestamp": "2024-03-09T05:00:00"}] | AY19: 4 | AZ19: 12 | BA19: 2 | BB19: 4.5183101 | BC19: 21.214856 | BD19: 11.139527 | BE19: 9.7505315 | BF19: 0.14544666 | BG19: 46.768672 | BH19: 39.39494 | BI19: 200 | BJ19: 146 | BK19: 12 | BL19: 94 | BM19: 35 | BN19: 656.77079 | BO19: Config | BP19: Fixed | BQ19: Completed | BR19: TC-7224 | BS19: FALSE | BU19: 1 | BV19: 0
A20: 190227 | B20: خالی بودن کمبو در گزارش تفضیلی در تمام مراجع همراه وثایق | C20: تکمیل توضیحات: خالی بودن کمبو در گزارش تفضیلی در تمام مراجع همراه... | D20: Medium | E20: P3 | F20: Done | G20: Data | H20: FALSE | I20: TRUE | J20: PRJ-001 | K20: Dem System | L20: Team Delta | M20: T04 | N20: M09 | O20: Dem\DemBiz\SP_88 | P20: Sprint 25 | Q20: S25 | R20: Data;Medium | T20: کامنت 4 مورد | U20: Mohammad Safari | V20: U093 | W20: Mohammad Safari | X20: U093 | Y20: Ali Rezaei | Z20: U374 | AA20: Reza Mohammadi | AB20: U493 | AC20: 2024-02-05 | AD20: 2024-02-05 16:00:00 | AE20: 2024-02-06 16:00:00 | AF20: 2024-02-09 14:00:00 | AG20: 2024-02-09 14:00:00 | AH20: 2024-02-11 07:00:00 | AI20: 2024-02-13 00:00:00 | AJ20: 2024-02-13 15:00:00 | AK20: 2024-02-13 15:00:00 | AM20: 2024-02-13 15:00:00 | AN20: 2024-03-20 | AO20: 0 | AR20: Resolved | AS20: 9 | AT20: 24 | AU20: 70 | AV20: 41 | AW20: 41 | AX20: [{"state": "Open", "timestamp": "2024-02-05T00:00:00"}, {"state": "Triage", "timestamp": "2024-02-05T16:00:00"}] | AY20: 0 | AZ20: 9 | BA20: 1 | BB20: 1.1771733 | BC20: 35.21755 | BD20: 18.858564 | BE20: 15.432588 | BF20: 0 | BG20: 70.685875 | BH20: 53.796862 | BK20: 40 | BL20: 135 | BM20: 41 | BN20: 689.77079 | BO20: Coding | BP20: Won't Fix | BR20: TC-6635 | BS20: FALSE | BU20: 3 | BV20: 0
A21: 190229 | B21: خالی بودن کمبو در گزارش درخواست های وارده به اداره کل اعتبارات | C21: تکمیل توضیحات: خالی بودن کمبو در گزارش درخواست های وارده به اداره... | D21: High | E21: P2 | F21: Closed | G21: Integration | H21: FALSE | I21: FALSE | J21: PRJ-001 | K21: Dem System | L21: Team Alpha | M21: T01 | N21: M09 | O21: Dem\DemBiz\SP_88 | P21: Sprint 25 | Q21: S25 | R21: Integration;High | S21: EXT-190229 | T21: کامنت 1 مورد | U21: Reza Mohammadi | V21: U493 | W21: Ali Rezaei | X21: U374 | Y21: Zahra Ebrahimi | Z21: U002 | AA21: Zahra Ebrahimi | AB21: U002 | AC21: 2024-04-12 | AD21: 2024-04-13 00:00:00 | AE21: 2024-04-13 08:00:00 | AF21: 2024-04-14 03:00:00 | AG21: 2024-04-14 03:00:00 | AH21: 2024-04-17 04:00:00 | AI21: 2024-04-18 15:00:00 | AJ21: 2024-04-18 19:00:00 | AK21: 2024-04-18 20:00:00 | AL21: 2024-04-19 04:00:00 | AM21: 2024-04-19 04:00:00 | AN21: 2024-04-28 | AO21: 1 | AP21: 2024-04-26 04:00:00 | AQ21: 2024-04-26 04:00:00 | AR21: Done | AS21: 9 | AT21: 8 | AU21: 19 | AV21: 73 | AW21: 35 | AX21: [{"state": "Open", "timestamp": "2024-04-12T00:00:00"}, {"state": "Triage", "timestamp": "2024-04-13T00:00:00"}] | AY21: 3 | AZ21: 9 | BA21: 2 | BB21: 6.7647687 | BC21: 29.889976 | BD21: 8.0290014 | BE21: 6.6230587 | BF21: 5.8991769 | BG21: 57.205982 | BH21: 45.290862 | BI21: 172 | BJ21: 121 | BK21: 32 | BL21: 62 | BM21: 73 | BN21: 622.77079 | BO21: Data | BP21: Fixed | BQ21: Completed | BS21: FALSE | BU21: 3 | BV21: 2
A22: 190238 | B22: خالی بودن کمبو واحد کارشناسی در گزارش گزارش محرک های هزینه یابی | C22: تکمیل توضیحات: خالی بودن کمبو واحد کارشناسی در گزارش گزارش محرک ه... | D22: Medium | E22: P3 | F22: Done | G22: UI | H22: FALSE | I22: FALSE | J22: PRJ-001 | K22: Dem System | L22: Team Beta | M22: T02 | N22: M09 | O22: Dem\DemBiz\SP_88 | P22: Sprint 23 | Q22: S23 | R22: UI;Medium | T22: کامنت 4 مورد | U22: Zahra Ebrahimi | V22: U002 | W22: Zahra Ebrahimi | X22: U002 | Y22: Hassan Karimi | Z22: U829 | AA22: Sara Ahmadi | AB22: U091 | AC22: 2024-06-01 | AD22: 2024-06-01 05:00:00 | AE22: 2024-06-01 18:00:00 | AF22: 2024-06-03 20:00:00 | AG22: 2024-06-03 20:00:00 | AH22: 2024-06-07 08:00:00 | AI22: 2024-06-08 17:00:00 | AJ22: 2024-06-09 11:00:00 | AK22: 2024-06-09 11:00:00 | AM22: 2024-06-09 11:00:00 | AN22: 2024-06-24 | AO22: 0 | AR22: Resolved | AS22: 7 | AT22: 13 | AU22: 50 | AV22: 84 | AW22: 33 | AX22: [{"state": "Open", "timestamp": "2024-06-01T00:00:00"}, {"state": "Triage", "timestamp": "2024-06-01T05:00:00"}] | AY22: 1 | AZ22: 8 | BA22: 1 | BB22: 2.9058505 | BC22: 28.183614 | BD22: 19.243216 | BE22: 5.2856813 | BF22: 0 | BG22: 55.618362 | BH22: 47.140713 | BK22: 18 | BL22: 96 | BM22: 84 | BN22: 572.77079 | BO22: Testing | BP22: Fixed | BS22: FALSE | BU22: 1 | BV22: 1
A23: 190240 | B23: خالی بودن کمبو ر گزارش آمار مصوبات صادره | C23: تکمیل توضیحات: خالی بودن کمبو ر گزارش آمار مصوبات صادره... | D23: High | E23: P3 | F23: Done | G23: Security | H23: FALSE | I23: FALSE | J23: PRJ-001 | K23: Dem System | L23: Team Alpha | M23: T01 | N23: M09 | O23: Dem\DemBiz\SP_88 | P23: Sprint 27 | Q23: S27 | R23: Security;High | T23: کامنت 0 مورد | U23: Mohammad Safari | V23: U093 | W23: Mina Hosseini | X23: U860 | Y23: Hassan Karimi | Z23: U829 | AA23: Mina Hosseini | AB23: U860 | AC23: 2024-05-21 | AD23: 2024-05-21 01:00:00 | AE23: 2024-05-21 23:00:00 | AF23: 2024-05-22 15:00:00 | AG23: 2024-05-22 15:00:00 | AH23: 2024-05-26 14:00:00 | AI23: 2024-05-28 04:00:00 | AJ23: 2024-05-28 14:00:00 | AK23: 2024-05-28 14:00:00 | AM23: 2024-05-28 14:00:00 | AN23: 2024-07-16 | AO23: 0 | AR23: Resolved | AS23: 6 | AT23: 22 | AU23: 16 | AV23: 95 | AW23: 38 | AX23: [{"state": "Open", "timestamp": "2024-05-21T00:00:00"}, {"state": "Triage", "timestamp": "2024-05-21T01:00:00"}] | AY23: 4 | AZ23: 8 | BA23: 1 | BB23: 1.8988888 | BC23: 28.396879 | BD23: 18.154338 | BE23: 14.028987 | BF23: 0 | BG23: 62.479093 | BH23: 49.758901 | BK23: 23 | BL23: 76 | BM23: 95 | BN23: 583.77079 | BO23: Design | BP23: By Design | BS23: FALSE | BU23: 3 | BV23: 0
A24: 190241 | B24: خالی بودن کمبو واحد کارشناسی در گزارش آمارتعداد پیشنهادات و مصوبات صادره | C24: تکمیل توضیحات: خالی بودن کمبو واحد کارشناسی در گزارش آمارتعداد پی... | D24: High | E24: P2 | F24: Triage | G24: Data | H24: FALSE | I24: FALSE | J24: PRJ-001 | K24: Dem System | L24: Team Delta | M24: T04 | N24: M09 | O24: Dem\DemBiz\SP_88 | P24: Sprint 26 | Q24: S26 | R24: Data;High | T24: کامنت 5 مورد | U24: Ali Rezaei | V24: U374 | W24: Zahra Ebrahimi | X24: U002 | AC24: 2024-06-13 | AD24: 2024-06-13 22:00:00 | AM24: 2024-06-13 22:00:00 | AN24: 2024-06-27 | AO24: 0 | AR24: Open | AS24: 2 | AX24: [{"state": "Open", "timestamp": "2024-06-13T00:00:00"}, {"state": "Triage", "timestamp": "2024-06-13T22:00:00"}] | AY24: 3 | AZ24: 4 | BA24: 1 | BB24: 0.80581356 | BC24: 15.020155 | BD24: 4.3179271 | BE24: 4.3539376 | BF24: 0 | BG24: 24.497833 | BH24: 19.890776 | BL24: 0 | BM24: 0 | BN24: 560.77079 | BR24: TC-7201 | BS24: FALSE | BU24: 0 | BV24: 0
A25: 190242 | B25: خالی بودن کمبو در گزارش آماری تسهیلات به تفکیک نوع عقود | C25: تکمیل توضیحات: خالی بودن کمبو در گزارش آماری تسهیلات به تفکیک نوع... | D25: Medium | E25: P1 | F25: In Progress | G25: UI | H25: FALSE | I25: FALSE | J25: PRJ-001 | K25: Dem System | L25: Team Delta | M25: T04 | N25: M09 | O25: Dem\DemBiz\SP_88 | P25: Sprint 24 | Q25: S24 | R25: UI;Medium | S25: EXT-190242 | T25: کامنت 2 مورد | U25: Hassan Karimi | V25: U829 | W25: Sara Ahmadi | X25: U091 | AC25: 2024-03-16 | AD25: 2024-03-17 04:00:00 | AE25: 2024-03-17 10:00:00 | AF25: 2024-03-19 22:00:00 | AG25: 2024-03-19 22:00:00 | AM25: 2024-03-19 22:00:00 | AN25: 2024-03-23 | AO25: 0 | AR25: Active | AS25: 6 | AT25: 6 | AU25: 60 | AX25: [{"state": "Open", "timestamp": "2024-03-16T00:00:00"}, {"state": "Triage", "timestamp": "2024-03-17T04:00:00"}] | AY25: 0 | AZ25: 7 | BA25: 1 | BB25: 4.9316971 | BC25: 12.450082 | BD25: 1.8525454 | BE25: 15.448338 | BF25: 0 | BG25: 34.682662 | BH25: 30.210579 | BK25: 34 | BL25: 66 | BM25: 0 | BN25: 649.77079 | BR25: TC-5803 | BS25: FALSE | BU25: 0 | BV25: 0
A26: 190243 | B26: خالی بودن کمبو در گزارش تعدادپرونده های وارده کارشناسان اداره کل اعتبارات | C26: تکمیل توضیحات: خالی بودن کمبو در گزارش تعدادپرونده های وارده کارش... | D26: Medium | E26: P1 | F26: In Progress | G26: Backend | H26: FALSE | I26: FALSE | J26: PRJ-001 | K26: Dem System | L26: Team Delta | M26: T04 | N26: M09 | O26: Dem\DemBiz\SP_88 | P26: Sprint 23 | Q26: S23 | R26: Backend;Medium | T26: کامنت 5 مورد | U26: Zahra Ebrahimi | V26: U002 | W26: Sara Ahmadi | X26: U091 | AC26: 2024-03-08 | AD26: 2024-03-09 09:00:00 | AE26: 2024-03-09 15:00:00 | AF26: 2024-03-12 09:00:00 | AG26: 2024-03-12 09:00:00 | AM26: 2024-03-12 09:00:00 | AN26: 2024-03-21 | AO26: 0 | AR26: Active | AS26: 6 | AT26: 6 | AU26: 66 | AX26: [{"state": "Open", "timestamp": "2024-03-08T00:00:00"}, {"state": "Triage", "timestamp": "2024-03-09T09:00:00"}] | AY26: 0 | AZ26: 8 | BA26: 1 | BB26: 5.5817327 | BC26: 32.565085 | BD26: 2.465171 | BE26: 1.1823171 | BF26: 0 | BG26: 41.794306 | BH26: 33.603632 | BK26: 39 | BL26: 72 | BM26: 0 | BN26: 657.77079 | BS26: FALSE | BU26: 0 | BV26: 0
A27: 190244 | B27: وجود ردیف خالی در کمبو نام مشتری در گزارش خلاصه پرونده | C27: تکمیل توضیحات: وجود ردیف خالی در کمبو نام مشتری در گزارش خلاصه پر... | D27: Low | E27: P2 | F27: In Progress | G27: Backend | H27: FALSE | I27: TRUE | J27: PRJ-001 | K27: Dem System | L27: Team Alpha | M27: T01 | N27: M09 | O27: Dem\DemBiz\SP_88 | P27: Sprint 23 | Q27: S23 | R27: Backend;Low | T27: کامنت 4 مورد | U27: Mina Hosseini | V27: U860 | W27: Hassan Karimi | X27: U829 | AC27: 2024-06-09 | AD27: 2024-06-09 20:00:00 | AE27: 2024-06-10 17:00:00 | AF27: 2024-06-13 11:00:00 | AG27: 2024-06-13 11:00:00 | AM27: 2024-06-13 11:00:00 | AN27: 2024-07-24 | AO27: 0 | AR27: Active | AS27: 4 | AT27: 21 | AU27: 66 | AX27: [{"state": "Open", "timestamp": "2024-06-09T00:00:00"}, {"state": "Triage", "timestamp": "2024-06-09T20:00:00"}] | AY27: 2 | AZ27: 6 | BA27: 1 | BB27: 0.62440872 | BC27: 32.594422 | BD27: 0.8553256 | BE27: 15.548182 | BF27: 0 | BG27: 49.622339 | BH27: 61.435396 | BK27: 41 | BL27: 87 | BM27: 0 | BN27: 564.77079 | BS27: FALSE | BU27: 0 | BV27: 0
A28: 190245 | B28: خالی بودن کمبو درگزارش درخواست های وارده مصوبات صادره | C28: تکمیل توضیحات: خالی بودن کمبو درگزارش درخواست های وارده مصوبات صا... | D28: High | E28: P3 | F28: Closed | G28: UI | H28: FALSE | I28: FALSE | J28: PRJ-001 | K28: Dem System | L28: Team Beta | M28: T02 | N28: M09 | O28: Dem\DemBiz\SP_88 | P28: Sprint 24 | Q28: S24 | R28: UI;High | S28: EXT-190245 | T28: کامنت 4 مورد | U28: Mina Hosseini | V28: U860 | W28: Reza Mohammadi | X28: U493 | Y28: Sara Ahmadi | Z28: U091 | AA28: Sara Ahmadi | AB28: U091 | AC28: 2024-02-20 | AD28: 2024-02-20 10:00:00 | AE28: 2024-02-20 22:00:00 | AF28: 2024-02-21 20:00:00 | AG28: 2024-02-21 20:00:00 | AH28: 2024-02-25 01:00:00 | AI28: 2024-02-26 14:00:00 | AJ28: 2024-02-26 16:00:00 | AK28: 2024-02-26 22:00:00 | AL28: 2024-02-28 06:00:00 | AM28: 2024-02-28 06:00:00 | AN28: 2024-02-28 | AO28: 0 | AR28: Done | AS28: 8 | AT28: 12 | AU28: 22 | AV28: 77 | AW28: 37 | AX28: [{"state": "Open", "timestamp": "2024-02-20T00:00:00"}, {"state": "Triage", "timestamp": "2024-02-20T10:00:00"}] | AY28: 2 | AZ28: 8 | BA28: 1 | BB28: 4.3406979 | BC28: 34.81582 | BD28: 2.3416377 | BE28: 1.6473987 | BF28: 0 | BG28: 43.145555 | BH28: 32.278926 | BI28: 198 | BJ28: 154 | BK28: 22 | BL28: 71 | BM28: 77 | BN28: 674.77079 | BO28: Data | BP28: Won't Fix | BQ28: Completed | BS28: FALSE | BU28: 1 | BV28: 1
A29: 190246 | B29: خالی بودن کمبو درگزارش مهلت ثبت مصوبه | C29: تکمیل توضیحات: خالی بودن کمبو درگزارش مهلت ثبت مصوبه... | D29: Medium | E29: P3 | F29: Ready for Retest | G29: Backend | H29: FALSE | I29: FALSE | J29: PRJ-001 | K29: Dem System | L29: Team Beta | M29: T02 | N29: M09 | O29: Dem\DemBiz\SP_88 | P29: Sprint 26 | Q29: S26 | R29: Backend;Medium | S29: EXT-190246 | T29: کامنت 1 مورد | U29: Sara Ahmadi | V29: U091 | W29: Sara Ahmadi | X29: U091 | AC29: 2024-04-02 | AD29: 2024-04-02 20:00:00 | AE29: 2024-04-03 04:00:00 | AF29: 2024-04-03 13:00:00 | AG29: 2024-04-03 13:00:00 | AH29: 2024-04-05 03:00:00 | AM29: 2024-04-05 03:00:00 | AN29: 2024-05-15 | AO29: 0 | AR29: In Progress | AS29: 5 | AT29: 8 | AU29: 9 | AV29: 38 | AX29: [{"state": "Open", "timestamp": "2024-04-02T00:00:00"}, {"state": "Triage", "timestamp": "2024-04-02T20:00:00"}] | AY29: 1 | AZ29: 7 | BA29: 1 | BB29: 2.1987183 | BC29: 36.616382 | BD29: 13.818632 | BE29: 14.367147 | BF29: 0 | BG29: 67.000879 | BH29: 67.986249 | BK29: 28 | BL29: 17 | BM29: 38 | BN29: 632.77079 | BR29: TC-2139 | BS29: FALSE | BU29: 0 | BV29: 0
A30: 190248 | B30: خالی بودن کمبو در گزارش مدت زمان توقف کارپرونده وارده به اداره کل اعتبارات | C30: تکمیل توضیحات: خالی بودن کمبو در گزارش مدت زمان توقف کارپرونده وا... | D30: Medium | E30: P0 | F30: Closed | G30: Integration | H30: FALSE | I30: FALSE | J30: PRJ-001 | K30: Dem System | L30: Team Alpha | M30: T01 | N30: M09 | O30: Dem\DemBiz\SP_88 | P30: Sprint 23 | Q30: S23 | R30: Integration;Medium | T30: کامنت 1 مورد | U30: Zahra Ebrahimi | V30: U002 | W30: Ali Rezaei | X30: U374 | Y30: Zahra Ebrahimi | Z30: U002 | AA30: Hassan Karimi | AB30: U829 | AC30: 2024-01-21 | AD30: 2024-01-21 06:00:00 | AE30: 2024-01-22 06:00:00 | AF30: 2024-01-24 22:00:00 | AG30: 2024-01-24 22:00:00 | AH30: 2024-01-29 14:00:00 | AI30: 2024-01-29 22:00:00 | AJ30: 2024-01-30 17:00:00 | AK30: 2024-01-30 20:00:00 | AL30: 2024-01-31 05:00:00 | AM30: 2024-01-31 05:00:00 | AN30: 2024-03-10 | AO30: 3 | AP30: 2024-02-09 05:00:00 | AQ30: 2024-02-10 05:00:00 | AR30: Done | AS30: 10 | AT30: 24 | AU30: 64 | AV30: 112 | AW30: 8 | AX30: [{"state": "Open", "timestamp": "2024-01-21T00:00:00"}, {"state": "Triage", "timestamp": "2024-01-21T06:00:00"}] | AY30: 3 | AZ30: 12 | BA30: 4 | BB30: 5.3387959 | BC30: 20.942354 | BD30: 1.8881786 | BE30: 8.9155166 | BF30: 25.870911 | BG30: 62.955756 | BH30: 59.571135 | BI30: 245 | BJ30: 151 | BK30: 30 | BL30: 96 | BM30: 112 | BN30: 704.77079 | BO30: Integration | BP30: Fixed | BQ30: Completed | BR30: TC-4733 | BS30: FALSE | BU30: 1 | BV30: 0
A31: 190250 | B31: حذف مشتری های خراب ، از کمبو مشتری در گزارشات | C31: تکمیل توضیحات: حذف مشتری های خراب ، از کمبو مشتری در گزارشات... | D31: Critical | E31: P2 | F31: Done | G31: Integration | H31: FALSE | I31: TRUE | J31: PRJ-001 | K31: Dem System | L31: Team Beta | M31: T02 | N31: M09 | O31: Dem\DemBiz\SP_88 | P31: Sprint 23 | Q31: S23 | R31: Integration;Critical | T31: کامنت 2 مورد | U31: Hassan Karimi | V31: U829 | W31: Zahra Ebrahimi | X31: U002 | Y31: Mina Hosseini | Z31: U860 | AA31: Ali Rezaei | AB31: U374 | AC31: 2024-03-08 | AD31: 2024-03-09 10:00:00 | AE31: 2024-03-10 06:00:00 | AF31: 2024-03-12 14:00:00 | AG31: 2024-03-12 14:00:00 | AH31: 2024-03-14 01:00:00 | AI31: 2024-03-15 15:00:00 | AJ31: 2024-03-16 15:00:00 | AK31: 2024-03-16 15:00:00 | AM31: 2024-03-16 15:00:00 | AN31: 2024-03-27 | AO31: 0 | AR31: Resolved | AS31: 9 | AT31: 20 | AU31: 56 | AV31: 35 | AW31: 38 | AX31: [{"state": "Open", "timestamp": "2024-03-08T00:00:00"}, {"state": "Triage", "timestamp": "2024-03-09T10:00:00"}] | AY31: 3 | AZ31: 10 | BA31: 1 | BB31: 1.8077482 | BC31: 20.559135 | BD31: 6.7200248 | BE31: 15.894472 | BF31: 0 | BG31: 44.98138 | BH31: 58.000214 | BK31: 54 | BL31: 114 | BM31: 35 | BN31: 657.77079 | BO31: Config | BP31: Fixed | BS31: FALSE | BU31: 1 | BV31: 1
A32: 190337 | B32: با ثبت بازه زمانی یکساله در گزارشات ، باز پیغام بازه یکساله می دهد | C32: تکمیل توضیحات: با ثبت بازه زمانی یکساله در گزارشات ، باز پیغام با... | D32: Medium | E32: P2 | F32: Closed | G32: UI | H32: FALSE | I32: FALSE | J32: PRJ-001 | K32: Dem System | L32: Team Alpha | M32: T01 | N32: M09 | O32: Dem\DemBiz\SP_88 | P32: Sprint 27 | Q32: S27 | R32: UI;Medium | T32: کامنت 1 مورد | U32: Fateme Akbari | V32: U511 | W32: Zahra Ebrahimi | X32: U002 | Y32: Zahra Ebrahimi | Z32: U002 | AA32: Mohammad Safari | AB32: U093 | AC32: 2024-03-20 | AD32: 2024-03-21 02:00:00 | AE32: 2024-03-22 00:00:00 | AF32: 2024-03-24 01:00:00 | AG32: 2024-03-24 01:00:00 | AH32: 2024-03-26 17:00:00 | AI32: 2024-03-28 06:00:00 | AJ32: 2024-03-28 22:00:00 | AK32: 2024-03-29 00:00:00 | AL32: 2024-03-29 16:00:00 | AM32: 2024-03-29 16:00:00 | AN32: 2024-04-10 | AO32: 0 | AR32: Done | AS32: 7 | AT32: 22 | AU32: 49 | AV32: 64 | AW32: 37 | AX32: [{"state": "Open", "timestamp": "2024-03-20T00:00:00"}, {"state": "Triage", "timestamp": "2024-03-21T02:00:00"}] | AY32: 2 | AZ32: 8 | BA32: 1 | BB32: 5.682033 | BC32: 32.133512 | BD32: 16.975069 | BE32: 2.1069485 | BF32: 0 | BG32: 56.897562 | BH32: 43.653138 | BI32: 232 | BJ32: 135 | BK32: 48 | BL32: 108 | BM32: 64 | BN32: 645.77079 | BO32: Data | BP32: Won't Fix | BQ32: Completed | BS32: FALSE | BU32: 3 | BV32: 1
A33: 190341 | B33: گزارش صورتهای مالی پایان دوره مشتری ، خالی نمایش داده می شود | C33: تکمیل توضیحات: گزارش صورتهای مالی پایان دوره مشتری ، خالی نمایش د... | D33: High | E33: P1 | F33: Resolved | G33: Data | H33: FALSE | I33: FALSE | J33: PRJ-001 | K33: Dem System | L33: Team Beta | M33: T02 | N33: M09 | O33: Dem\DemBiz\SP_88 | P33: Sprint 26 | Q33: S26 | R33: Data;High | T33: کامنت 4 مورد | U33: Reza Mohammadi | V33: U493 | W33: Hassan Karimi | X33: U829 | Y33: Mohammad Safari | Z33: U093 | AA33: Ali Rezaei | AB33: U374 | AC33: 2024-03-27 | AD33: 2024-03-27 02:00:00 | AE33: 2024-03-27 21:00:00 | AF33: 2024-03-30 21:00:00 | AG33: 2024-03-30 21:00:00 | AH33: 2024-04-01 10:00:00 | AI33: 2024-04-03 03:00:00 | AM33: 2024-04-03 03:00:00 | AN33: 2024-04-17 | AO33: 0 | AR33: Ready for Retest | AS33: 5 | AT33: 19 | AU33: 72 | AV33: 37 | AW33: 41 | AX33: [{"state": "Open", "timestamp": "2024-03-27T00:00:00"}, {"state": "Triage", "timestamp": "2024-03-27T02:00:00"}] | AY33: 3 | AZ33: 5 | BA33: 1 | BB33: 3.4005151 | BC33: 26.348593 | BD33: 0.95380275 | BE33: 9.3078143 | BF33: 0 | BG33: 40.010725 | BH33: 37.558602 | BK33: 21 | BL33: 132 | BM33: 37 | BN33: 638.77079 | BO33: Testing | BP33: Fixed | BS33: FALSE | BU33: 0 | BV33: 0
A34: 190576 | B34: گزینه های مطالبات از کمبو مروبطه حذف گردد | C34: تکمیل توضیحات: گزینه های مطالبات از کمبو مروبطه حذف گردد... | D34: Critical | E34: P1 | F34: Done | G34: Data | H34: TRUE | I34: FALSE | J34: PRJ-001 | K34: Dem System | L34: Team Gamma | M34: T03 | N34: M09 | O34: Dem\DemBiz\SP_88 | P34: Sprint 23 | Q34: S23 | R34: Data;Critical | T34: کامنت 4 مورد | U34: Ali Rezaei | V34: U374 | W34: Mohammad Safari | X34: U093 | Y34: Ali Rezaei | Z34: U374 | AA34: Mina Hosseini | AB34: U860 | AC34: 2024-01-02 | AD34: 2024-01-02 05:00:00 | AE34: 2024-01-03 04:00:00 | AF34: 2024-01-03 13:00:00 | AG34: 2024-01-03 13:00:00 | AH34: 2024-01-05 02:00:00 | AI34: 2024-01-05 10:00:00 | AJ34: 2024-01-05 13:00:00 | AK34: 2024-01-05 13:00:00 | AM34: 2024-01-05 13:00:00 | AN34: 2024-01-30 | AO34: 0 | AR34: Resolved | AS34: 9 | AT34: 23 | AU34: 9 | AV34: 37 | AW34: 8 | AX34: [{"state": "Open", "timestamp": "2024-01-02T00:00:00"}, {"state": "Triage", "timestamp": "2024-01-02T05:00:00"}] | AY34: 3 | AZ34: 11 | BA34: 1 | BB34: 7.5254749 | BC34: 28.376708 | BD34: 16.382135 | BE34: 15.539538 | BF34: 0 | BG34: 67.823857 | BH34: 86.928634 | BK34: 28 | BL34: 40 | BM34: 37 | BN34: 723.77079 | BO34: Integration | BP34: Fixed | BS34: FALSE | BU34: 3 | BV34: 0
A35: 190586 | B35: کمبو اقدام کننده در فرم انتخاب کارشناس | C35: تکمیل توضیحات: کمبو اقدام کننده در فرم انتخاب کارشناس... | D35: Low | E35: P2 | F35: Resolved | G35: UI | H35: FALSE | I35: FALSE | J35: PRJ-001 | K35: Dem System | L35: Team Gamma | M35: T03 | N35: M09 | O35: Dem\DemBiz\SP_88 | P35: Sprint 26 | Q35: S26 | R35: UI;Low | T35: کامنت 0 مورد | U35: Sara Ahmadi | V35: U091 | W35: Mohammad Safari | X35: U093 | Y35: Ali Rezaei | Z35: U374 | AA35: Ali Rezaei | AB35: U374 | AC35: 2024-01-19 | AD35: 2024-01-20 09:00:00 | AE35: 2024-01-20 17:00:00 | AF35: 2024-01-22 06:00:00 | AG35: 2024-01-22 06:00:00 | AH35: 2024-01-26 03:00:00 | AI35: 2024-01-27 14:00:00 | AM35: 2024-01-27 14:00:00 | AN35: 2024-02-08 | AO35: 0 | AR35: Ready for Retest | AS35: 6 | AT35: 8 | AU35: 37 | AV35: 93 | AW35: 35 | AX35: [{"state": "Open", "timestamp": "2024-01-19T00:00:00"}, {"state": "Triage", "timestamp": "2024-01-20T09:00:00"}] | AY35: 0 | AZ35: 8 | BA35: 1 | BB35: 1.5314071 | BC35: 32.035914 | BD35: 5.9961681 | BE35: 8.8464677 | BF35: 0 | BG35: 48.409957 | BH35: 59.026467 | BK35: 41 | BL35: 80 | BM35: 93 | BN35: 706.77079 | BO35: Design | BP35: Fixed | BR35: TC-8428 | BS35: FALSE | BU35: 0 | BV35: 1
A36: 190788 | B36: باگ های ویرایش عقود به جز حد و سقف و مشارکتی | C36: تکمیل توضیحات: باگ های ویرایش عقود به جز حد و سقف و مشارکتی... | D36: Low | E36: P3 | F36: Active | G36: Data | H36: FALSE | I36: FALSE | J36: PRJ-001 | K36: Dem System | L36: Team Delta | M36: T04 | N36: M09 | O36: Dem\DemBiz\SP_88 | P36: Sprint 24 | Q36: S24 | R36: Data;Low | T36: کامنت 4 مورد | U36: Mina Hosseini | V36: U860 | W36: Mina Hosseini | X36: U860 | AC36: 2024-05-18 | AD36: 2024-05-18 09:00:00 | AE36: 2024-05-19 09:00:00 | AM36: 2024-05-19 09:00:00 | AN36: 2024-06-30 | AO36: 0 | AR36: Triage | AS36: 3 | AT36: 24 | AX36: [{"state": "Open", "timestamp": "2024-05-18T00:00:00"}, {"state": "Triage", "timestamp": "2024-05-18T09:00:00"}] | AY36: 2 | AZ36: 5 | BA36: 1 | BB36: 3.0579976 | BC36: 35.710208 | BD36: 2.8042141 | BE36: 10.44098 | BF36: 0 | BG36: 52.0134 | BH36: 61.908597 | BK36: 33 | BL36: 24 | BM36: 0 | BN36: 586.77079 | BS36: FALSE | BU36: 0 | BV36: 0
A37: 190916 | B37: دکمه تایید و ادامه در فرم ورود اطلاعات پیشنهاد شعبه پیغام خطا می دهد | C37: تکمیل توضیحات: دکمه تایید و ادامه در فرم ورود اطلاعات پیشنهاد شعب... | D37: Low | E37: P2 | F37: Closed | G37: Data | H37: FALSE | I37: FALSE | J37: PRJ-001 | K37: Dem System | L37: Team Gamma | M37: T03 | N37: M09 | O37: Dem\DemBiz\SP_88 | P37: Sprint 25 | Q37: S25 | R37: Data;Low | T37: کامنت 2 مورد | U37: Reza Mohammadi | V37: U493 | W37: Hassan Karimi | X37: U829 | Y37: Mohammad Safari | Z37: U093 | AA37: Ali Rezaei | AB37: U374 | AC37: 2024-05-27 | AD37: 2024-05-28 07:00:00 | AE37: 2024-05-28 15:00:00 | AF37: 2024-05-31 05:00:00 | AG37: 2024-05-31 05:00:00 | AH37: 2024-06-04 20:00:00 | AI37: 2024-06-06 02:00:00 | AJ37: 2024-06-06 10:00:00 | AK37: 2024-06-06 12:00:00 | AL37: 2024-06-06 19:00:00 | AM37: 2024-06-06 19:00:00 | AN37: 2024-07-15 | AO37: 3 | AP37: 2024-06-12 19:00:00 | AQ37: 2024-06-15 19:00:00 | AR37: Done | AS37: 7 | AT37: 8 | AU37: 62 | AV37: 111 | AW37: 30 | AX37: [{"state": "Open", "timestamp": "2024-05-27T00:00:00"}, {"state": "Triage", "timestamp": "2024-05-28T07:00:00"}] | AY37: 4 | AZ37: 7 | BA37: 4 | BB37: 1.3510514 | BC37: 14.181811 | BD37: 14.086375 | BE37: 11.43623 | BF37: 29.400977 | BG37: 70.456445 | BH37: 60.222061 | BI37: 259 | BJ37: 158 | BK37: 39 | BL37: 100 | BM37: 111 | BN37: 577.77079 | BO37: Design | BP37: Fixed | BQ37: Cannot Reproduce | BR37: TC-7065 | BS37: FALSE | BU37: 1 | BV37: 2
A38: 145770 | B38: فرم تکمیل اطلاعات/تب نظریه کارشناسی/فیلد پرونده های الکترونیک | C38: تکمیل توضیحات: فرم تکمیل اطلاعات/تب نظریه کارشناسی/فیلد پرونده ها... | D38: High | E38: P2 | F38: In Progress | G38: Integration | H38: FALSE | I38: FALSE | J38: PRJ-001 | K38: Dem System | L38: Team Gamma | M38: T03 | N38: M09 | O38: Dem\DemBiz\SP_88 | P38: Sprint 23 | Q38: S23 | R38: Integration;High | T38: کامنت 3 مورد | U38: Reza Mohammadi | V38: U493 | W38: Fateme Akbari | X38: U511 | AC38: 2024-04-15 | AD38: 2024-04-16 06:00:00 | AE38: 2024-04-17 06:00:00 | AF38: 2024-04-17 14:00:00 | AG38: 2024-04-17 14:00:00 | AM38: 2024-04-17 14:00:00 | AN38: 2024-06-04 | AO38: 0 | AR38: Active | AS38: 6 | AT38: 24 | AU38: 8 | AX38: [{"state": "Open", "timestamp": "2024-04-15T00:00:00"}, {"state": "Triage", "timestamp": "2024-04-16T06:00:00"}] | AY38: 2 | AZ38: 6 | BA38: 1 | BB38: 7.4352021 | BC38: 15.647735 | BD38: 12.764386 | BE38: 7.818116 | BF38: 0 | BG38: 43.665439 | BH38: 35.042936 | BK38: 54 | BL38: 32 | BM38: 0 | BN38: 619.77079 | BR38: TC-5374 | BS38: FALSE | BU38: 0 | BV38: 0
A39: 194846 | B39: رفع باگ / بررسی کاستومر هایی که فیلد Updatefw = 225135 | C39: تکمیل توضیحات: رفع باگ / بررسی کاستومر هایی که فیلد Updatefw = 22... | D39: Critical | E39: P3 | F39: Open | G39: Data | H39: FALSE | I39: TRUE | J39: PRJ-001 | K39: Dem System | L39: Team Gamma | M39: T03 | N39: M09 | O39: Dem\DemBiz\SP_88 | P39: Sprint 27 | Q39: S27 | R39: Data;Critical | T39: کامنت 0 مورد | U39: Ali Rezaei | V39: U374 | W39: Mina Hosseini | X39: U860 | AC39: 2024-06-16 | AM39: 2024-06-16 00:00:00 | AN39: 2024-08-03 | AO39: 0 | AS39: 1 | AX39: [{"state": "Open", "timestamp": "2024-06-16T00:00:00"}, {"state": "Triage", "timestamp": ""}] | AY39: 4 | AZ39: 2 | BA39: 1 | BB39: 7.0800452 | BC39: 4.6652957 | BD39: 17.610704 | BE39: 10.413371 | BF39: 0 | BG39: 39.769416 | BH39: 43.793522 | BL39: 0 | BM39: 0 | BN39: 557.77079 | BS39: FALSE | BU39: 0 | BV39: 0
A40: 190892 | B40: حد و سقف اعتباری مشارکت مدنی ویژه >کمبو از تاریخ صدور/تصویب> اجباریه ولی ستاره نداره | C40: تکمیل توضیحات: حد و سقف اعتباری مشارکت مدنی ویژه >کمبو از تاریخ ص... | D40: Medium | E40: P2 | F40: Done | G40: Performance | H40: FALSE | I40: FALSE | J40: PRJ-001 | K40: Dem System | L40: Team Alpha | M40: T01 | N40: M09 | O40: Dem\DemBiz\SP_88 | P40: Sprint 24 | Q40: S24 | R40: Performance;Medium | T40: کامنت 0 مورد | U40: Fateme Akbari | V40: U511 | W40: Fateme Akbari | X40: U511 | Y40: Zahra Ebrahimi | Z40: U002 | AA40: Mina Hosseini | AB40: U860 | AC40: 2024-01-26 | AD40: 2024-01-26 04:00:00 | AE40: 2024-01-26 17:00:00 | AF40: 2024-01-28 14:00:00 | AG40: 2024-01-28 14:00:00 | AH40: 2024-02-02 04:00:00 | AI40: 2024-02-02 14:00:00 | AJ40: 2024-02-02 23:00:00 | AK40: 2024-02-02 23:00:00 | AM40: 2024-02-02 23:00:00 | AN40: 2024-02-14 | AO40: 0 | AR40: Resolved | AS40: 6 | AT40: 13 | AU40: 45 | AV40: 110 | AW40: 10 | AX40: [{"state": "Open", "timestamp": "2024-01-26T00:00:00"}, {"state": "Triage", "timestamp": "2024-01-26T04:00:00"}] | AY40: 0 | AZ40: 6 | BA40: 1 | BB40: 2.4345622 | BC40: 23.552925 | BD40: 14.833885 | BE40: 9.7647147 | BF40: 0 | BG40: 50.586088 | BH40: 63.618359 | BK40: 17 | BL40: 68 | BM40: 110 | BN40: 699.77079 | BO40: Testing | BP40: Duplicate | BS40: TRUE | BT40: 192406 | BU40: 1 | BV40: 0
...

Sheet metrics
A1: Code | B1: Metric_Name | C1: Value | D1: Formula_Text | E1: Description
A2: B03 | B2: B03_Revenue_at_Risk | C2: 0 | D2: =SUM('Bugs'[BusinessImpact]) | E2: Auto-generated from MD: Revenue at Risk
A3: B04 | B3: B04_Avg_Revenue_Impact_per_Bug | C3: 0 | D3: =AVERAGE('Bugs'[BusinessImpact]) | E3: Auto-generated from MD: Avg Revenue Impact per Bug
A4: B05 | B4: B05_High_Impact_Bugs | C4: 0 | D4: =CALCULATE(COUNTA(raw_data!A:A)-1, 'Bugs'[BusinessImpact] > 10000) | E4: Auto-generated from MD: High Impact Bugs
A5: B09 | B5: B09_Security_Risk_Level | C5: 0 | D5: =SWITCH(TRUE(), [V23_Security_Bugs] > 10, "High", [V23_Security_Bugs] > 5, "Medium", "Low" ) | E5: Auto-generated from MD: Security Risk Level
A6: B10 | B6: B10_Compliance_Risk_Bugs | C6: 0 | D6: =CALCULATE(COUNTA(raw_data!A:A)-1, 'Bugs'[Category] = "Compliance") | E6: Auto-generated from MD: Compliance Risk Bugs
A7: B11 | B7: B11_Data_Loss_Risk_Bugs | C7: 0 | D7: =CALCULATE(COUNTA(raw_data!A:A)-1, 'Bugs'[Category] = "Data Loss") | E7: Auto-generated from MD: Data Loss Risk Bugs
A8: B12 | B8: B12_Critical_Business_Impact_Bugs | C8: 0 | D8: =CALCULATE( COUNTA(raw_data!A:A)-1, raw_data!D:D = "Critical", 'Bugs'[BusinessImpact] > 0 ) | E8: Auto-generated from MD: Critical Business Impact Bugs
A9: B13 | B9: B13_Cost_of_Poor_Quality | C9: 0 | D9: =[J18_Project_Cost_of_Quality] | E9: Auto-generated from MD: Cost of Poor Quality
A10: B14 | B10: B14_Avg_Impact_by_Severity | C10: 0 | D10: =AVERAGEX( VALUES(raw_data!D:D), CALCULATE(AVERAGE('Bugs'[BusinessImpact])) ) | E10: Auto-generated from MD: Avg Impact by Severity
A11: B15 | B11: B15_Total_Business_Impact | C11: 0 | D11: =SUM('Bugs'[BusinessImpact]) | E11: Auto-generated from MD: Total Business Impact
A12: B16 | B12: B16_Impact_per_Module | C12: 0 | D12: =AVERAGEX( VALUES('Bugs'[ModuleName]), CALCULATE(SUM('Bugs'[BusinessImpact])) ) | E12: Auto-generated from MD: Impact per Module
A13: B17 | B13: B17_High_Severity_Impact | C13: 0 | D13: =CALCULATE( SUM('Bugs'[BusinessImpact]), raw_data!D:D IN {"Critical", "High"} ) | E13: Auto-generated from MD: High Severity Impact
A14: B18 | B14: B18_Production_Bug_Impact | C14: 0 | D14: =CALCULATE( SUM('Bugs'[BusinessImpact]), 'Bugs'[Tags] CONTAINS "Production" ) | E14: Auto-generated from MD: Production Bug Impact
A15: B19 | B15: B19_Escaped_Bug_Impact | C15: 0 | D15: =CALCULATE( SUM('Bugs'[BusinessImpact]), raw_data!I:I = TRUE ) | E15: Auto-generated from MD: Escaped Bug Impact
A16: B20 | B16: B20_Impact_Risk_Score | C16: 0 | D16: =([B15_Total_Business_Impact] * 0.4) + ([B19_Escaped_Bug_Impact] * 0.35) + ([B17_High_Severity_Impact] * 0.25) | E16: Auto-generated from MD: Impact Risk Score
A17: B21 | B17: B21_Avg_Resolution_Cost | C17: 0 | D17: =AVERAGE('Bugs'[TotalEffortHrs]) * 100 | E17: Auto-generated from MD: Avg Resolution Cost
A18: B22 | B18: B22_Security_Bug_Impact | C18: 0 | D18: =CALCULATE( SUM('Bugs'[BusinessImpact]), 'Bugs'[Category] = "Security" ) | E18: Auto-generated from MD: Security Bug Impact
A19: B23 | B19: B23_Performance_Bug_Impact | C19: 0 | D19: =CALCULATE( SUM('Bugs'[BusinessImpact]), 'Bugs'[Category] = "Performance" ) | E19: Auto-generated from MD: Performance Bug Impact
